Workbook

Sheet Premissas
A1: Zelo — Premissas (todas são hipóteses a validar)
A2: Edite as células em azul. Amarelo = premissas que mais mexem no resultado.
A4: PREÇOS (o que a família paga)
A5: Acompanhante (bloco de até 4h) | B5: 180 | C5: Sugestão do grupo; entrevista: ~R$ 300 pelo DIA inteiro
A6: Transporte ida e volta (até 15 km) | B6: 80 | C6: Definido pelo grupo
A7: Adicional veículo adaptado (rampa) | B7: 60 | C7: Estimativa
A8: Taxa de serviço por atendimento (plano Grátis) | B8: 15 | C8: Isenta no Zelo+ e no Zelo Empresas
A9: Zelo+ (mensal por família) | B9: 29.9 | C9: Definido pelo grupo
A10: ZELO EMPRESAS (o que a empresa paga)
A11: Mensalidade por funcionário (todos os funcionários) | B11: 5 | C11: Modelo de benefício: a empresa paga por funcionário, use ou não. Inclui Zelo+ para quem tem pais idosos
A12: Funcionários por empresa cliente (média) | B12: 500 | C12: Empresas médias e grandes de SP
A13: MIX DOS ATENDIMENTOS
A14: % dos atendimentos com acompanhante | B14: 0.8 | C14: Estimativa
A15: % dos atendimentos com transporte | B15: 0.95 | C15: Estimativa
A16: % dos atendimentos com veículo adaptado | B16: 0.1 | C16: Estimativa
A17: CUSTOS VARIÁVEIS
A18: Repasse ao acompanhante (% do preço) | B18: 0.75 | C18: Zelo fica com 25%
A19: Custo do carro ida e volta (99/Uber/táxi) | B19: 60 | C19: Estimativa: 2 corridas de ~6 km em SP
A20: Custo adicional da frota adaptada | B20: 45 | C20: Estimativa
A21: Taxa de pagamento (% do valor cobrado) | B21: 0.03 | C21: Cartão/Pix intermediado; não incide no boleto B2B
A22: Seguro de acidentes pessoais por atendimento | B22: 4 | C22: Estimativa
A23: IA + WhatsApp por atendimento | B23: 3 | C23: Conversa de agendamento + avisos do dia
A24: IA + WhatsApp por família ativa no mês | B24: 1.5 | C24: Lembretes, perguntas
A25: Impostos sobre a receita própria do Zelo | B25: 0.08 | C25: Simples Nacional, estimativa. Base = entradas − repasses − carros

Sheet DRE 3 anos
A1: Zelo — DRE preliminar de 3 anos (R$ por ano)
A2: Cenário-base · modelo: acompanhante Zelo + carro sob demanda · B2B cobrado por funcionário
A4: Linha | B4: Ano 1 | C4: Ano 2 | D4: Ano 3 | E4: Como é calculado
A5: VOLUME (premissas de cada ano, média mensal)
A6: Famílias B2C ativas | B6: 250 | C6: 1000 | D6: 2500 | E6: famílias que contratam por conta própria
A7: % das famílias B2C no Zelo+ | B7: 0.15 | C7: 0.2 | D7: 0.25
A8: Atendimentos por família B2C por mês | B8: 0.8 | C8: 0.8 | D8: 0.8
A9: Empresas clientes (média no ano) | B9: 5 | C9: 30 | D9: 90 | E9: ex.: piloto com 3 empresas, 5 no fim do ano 1
A10: % dos funcionários com família ativa no mês | B10: 0.03 | C10: 0.04 | D10: 0.05 | E10: funcionários de 35 a 60 anos que levam os pais ao médico
A11: Atendimentos por família B2B por mês | B11: 1 | C11: 1 | D11: 1 | E11: o benefício estimula o uso
A12: Funcionários cobertos | B12: =B9*Premissas!$B$12 -> 2500 | C12: =C9*Premissas!$B$12 -> 15000 | D12: =D9*Premissas!$B$12 -> 45000
A13: Famílias B2B ativas | B13: =B12*B10 -> 75 | C13: =C12*C10 -> 600 | D13: =D12*D10 -> 2250
A14: Atendimentos por mês | B14: =B6*B8+B13*B11 -> 275 | C14: =C6*C8+C13*C11 -> 1400 | D14: =D6*D8+D13*D11 -> 4250
A15: Atendimentos no ano | B15: =B14*12 -> 3300 | C15: =C14*12 -> 16800 | D15: =D14*12 -> 51000
A16: % dos atendimentos vindos do B2B | B16: =IF(B14=0,0,B13*B11/B14) -> 0.27272727 | C16: =IF(C14=0,0,C13*C11/C14) -> 0.42857143 | D16: =IF(D14=0,0,D13*D11/D14) -> 0.52941176
A17: % dos atendimentos isentos da taxa | B17: =IF(B14=0,0,(B6*B7*B8+B13*B11)/B14) -> 0.38181818 | C17: =IF(C14=0,0,(C6*C7*C8+C13*C11)/C14) -> 0.54285714 | D17: =IF(D14=0,0,(D6*D7*D8+D13*D11)/D14) -> 0.64705882 | E17: famílias Zelo+ e Zelo Empresas não pagam taxa
A19: ENTRADAS (dinheiro que entra)
A20: Acompanhantes | B20: =B15*Premissas!$B$14*Premissas!$B$5 -> 475200 | C20: =C15*Premissas!$B$14*Premissas!$B$5 -> 2419200 | D20: =D15*Premissas!$B$14*Premissas!$B$5 -> 7344000 | E20: atendimentos × % com acompanhante × preço
A21: Transporte | B21: =B15*Premissas!$B$15*Premissas!$B$6 -> 250800 | C21: =C15*Premissas!$B$15*Premissas!$B$6 -> 1276800 | D21: =D15*Premissas!$B$15*Premissas!$B$6 -> 3876000
A22: Adicional veículo adaptado | B22: =B15*Premissas!$B$16*Premissas!$B$7 -> 19800 | C22: =C15*Premissas!$B$16*Premissas!$B$7 -> 100800 | D22: =D15*Premissas!$B$16*Premissas!$B$7 -> 306000
A23: Taxa de serviço (plano Grátis) | B23: =B15*(1-B17)*Premissas!$B$8 -> 30600 | C23: =C15*(1-C17)*Premissas!$B$8 -> 115200 | D23: =D15*(1-D17)*Premissas!$B$8 -> 270000
A24: Assinaturas Zelo+ | B24: =B6*B7*Premissas!$B$9*12 -> 13455 | C24: =C6*C7*Premissas!$B$9*12 -> 71760 | D24: =D6*D7*Premissas!$B$9*12 -> 224250
A25: Zelo Empresas (mensalidade por funcionário) | B25: =B12*Premissas!$B$11*12 -> 150000 | C25: =C12*Premissas!$B$11*12 -> 900000 | D25: =D12*Premissas!$B$11*12 -> 2700000 | E25: receita recorrente, faturada por boleto à empresa
A26: Total de entradas | B26: =SUM(B20:B25) -> 939855 | C26: =SUM(C20:C25) -> 4883760 | D26: =SUM(D20:D25) -> 14720250
A27: Receita própria do Zelo (entradas − repasses − carros) | B27: =B26+B30+B31+B32 -> 380505 | C27: =C26+C30+C31+C32 -> 2036160 | D27: =D26+D30+D31+D32 -> 6075750 | E27: o que é de fato do Zelo
A29: SAÍDAS VARIÁVEIS
A30: Repasse aos acompanhantes | B30: =-B20*Premissas!$B$18 -> -356400 | C30: =-C20*Premissas!$B$18 -> -1814400 | D30: =-D20*Premissas!$B$18 -> -5508000
A31: Carros sob demanda (99/Uber/táxi) | B31: =-B15*Premissas!$B$15*Premissas!$B$19 -> -188100 | C31: =-C15*Premissas!$B$15*Premissas!$B$19 -> -957600 | D31: =-D15*Premissas!$B$15*Premissas!$B$19 -> -2907000
A32: Frota adaptada parceira | B32: =-B15*Premissas!$B$16*Premissas!$B$20 -> -14850 | C32: =-C15*Premissas!$B$16*Premissas!$B$20 -> -75600 | D32: =-D15*Premissas!$B$16*Premissas!$B$20 -> -229500
A33: Taxa de pagamento | B33: =-(B26-B25)*Premissas!$B$21 -> -23695.65 | C33: =-(C26-C25)*Premissas!$B$21 -> -119512.8 | D33: =-(D26-D25)*Premissas!$B$21 -> -360607.5 | E33: sobre tudo, menos o boleto B2B
A34: Seguro por atendimento | B34: =-B15*Premissas!$B$22 -> -13200 | C34: =-C15*Premissas!$B$22 -> -67200 | D34: =-D15*Premissas!$B$22 -> -204000
A35: IA + WhatsApp | B35: =-(B15*Premissas!$B$23+(B6+B13)*12*Premissas!$B$24) -> -15750 | C35: =-(C15*Premissas!$B$23+(C6+C13)*12*Premissas!$B$24) -> -79200 | D35: =-(D15*Premissas!$B$23+(D6+D13)*12*Premissas!$B$24) -> -238500
A36: Impostos sobre a receita própria | B36: =-B27*Premissas!$B$25 -> -30440.4 | C36: =-C27*Premissas!$B$25 -> -162892.8 | D36: =-D27*Premissas!$B$25 -> -486060
A37: Margem de contribuição | B37: =B26+SUM(B30:B36) -> 297418.95 | C37: =C26+SUM(C30:C36) -> 1607354.4 | D37: =D26+SUM(D30:D36) -> 4786582.5
A38: Margem de contribuição (% das entradas) | B38: =IF(B26=0,0,B37/B26) -> 0.31645195 | C38: =IF(C26=0,0,C37/C26) -> 0.32912232 | D38: =IF(D26=0,0,D37/D26) -> 0.32516992
A40: CUSTOS FIXOS (média mensal no ano; azul = editável)
A41: Equipe de operação e atendimento (com encargos) | B41: 12000 | C41: 32000 | D41: 60000 | E41: 2 / 5 / 9 pessoas; a Zélia faz o agendamento
A42: Pró-labore dos fundadores | B42: 9000 | C42: 18000 | D42: 30000 | E42: 3 fundadores
A43: Tecnologia (desenvolvimento e nuvem) | B43: 10000 | C43: 25000 | D43: 40000
A44: Marketing e aquisição de famílias B2C | B44: 8000 | C44: 15000 | D44: 25000 | E44: menor porque o B2B traz famílias sem custo de aquisição
...

Sheet Sensibilidade
A1: EBIT por ano conforme a mensalidade por funcionário do Zelo Empresas
A2: Cada R$ 1 a mais por funcionário vira receita quase sem custo (só imposto). Demais premissas como na DRE.
A4: R$ por funcionário/mês | B4: Ano 1 | C4: Ano 2 | D4: Ano 3
A5: 0 | B5: ='DRE 3 anos'!B54+'DRE 3 anos'!B12*12*($A5-Premissas!$B$11)*(1-Premissas!$B$25) -> -506581.05 | C5: ='DRE 3 anos'!C54+'DRE 3 anos'!C12*12*($A5-Premissas!$B$11)*(1-Premissas!$B$25) -> -680645.6 | D5: ='DRE 3 anos'!D54+'DRE 3 anos'!D12*12*($A5-Premissas!$B$11)*(1-Premissas!$B$25) -> -257417.5
A6: 2 | B6: ='DRE 3 anos'!B54+'DRE 3 anos'!B12*12*($A6-Premissas!$B$11)*(1-Premissas!$B$25) -> -451381.05 | C6: ='DRE 3 anos'!C54+'DRE 3 anos'!C12*12*($A6-Premissas!$B$11)*(1-Premissas!$B$25) -> -349445.6 | D6: ='DRE 3 anos'!D54+'DRE 3 anos'!D12*12*($A6-Premissas!$B$11)*(1-Premissas!$B$25) -> 736182.5
A7: 3 | B7: ='DRE 3 anos'!B54+'DRE 3 anos'!B12*12*($A7-Premissas!$B$11)*(1-Premissas!$B$25) -> -423781.05 | C7: ='DRE 3 anos'!C54+'DRE 3 anos'!C12*12*($A7-Premissas!$B$11)*(1-Premissas!$B$25) -> -183845.6 | D7: ='DRE 3 anos'!D54+'DRE 3 anos'!D12*12*($A7-Premissas!$B$11)*(1-Premissas!$B$25) -> 1232982.5
A8: 4 | B8: ='DRE 3 anos'!B54+'DRE 3 anos'!B12*12*($A8-Premissas!$B$11)*(1-Premissas!$B$25) -> -396181.05 | C8: ='DRE 3 anos'!C54+'DRE 3 anos'!C12*12*($A8-Premissas!$B$11)*(1-Premissas!$B$25) -> -18245.6 | D8: ='DRE 3 anos'!D54+'DRE 3 anos'!D12*12*($A8-Premissas!$B$11)*(1-Premissas!$B$25) -> 1729782.5
A9: 5 | B9: ='DRE 3 anos'!B54+'DRE 3 anos'!B12*12*($A9-Premissas!$B$11)*(1-Premissas!$B$25) -> -368581.05 | C9: ='DRE 3 anos'!C54+'DRE 3 anos'!C12*12*($A9-Premissas!$B$11)*(1-Premissas!$B$25) -> 147354.4 | D9: ='DRE 3 anos'!D54+'DRE 3 anos'!D12*12*($A9-Premissas!$B$11)*(1-Premissas!$B$25) -> 2226582.5
A10: 6 | B10: ='DRE 3 anos'!B54+'DRE 3 anos'!B12*12*($A10-Premissas!$B$11)*(1-Premissas!$B$25) -> -340981.05 | C10: ='DRE 3 anos'!C54+'DRE 3 anos'!C12*12*($A10-Premissas!$B$11)*(1-Premissas!$B$25) -> 312954.4 | D10: ='DRE 3 anos'!D54+'DRE 3 anos'!D12*12*($A10-Premissas!$B$11)*(1-Premissas!$B$25) -> 2723382.5
A11: 8 | B11: ='DRE 3 anos'!B54+'DRE 3 anos'!B12*12*($A11-Premissas!$B$11)*(1-Premissas!$B$25) -> -285781.05 | C11: ='DRE 3 anos'!C54+'DRE 3 anos'!C12*12*($A11-Premissas!$B$11)*(1-Premissas!$B$25) -> 644154.4 | D11: ='DRE 3 anos'!D54+'DRE 3 anos'!D12*12*($A11-Premissas!$B$11)*(1-Premissas!$B$25) -> 3716982.5

Sheet Por atendimento
A1: Um atendimento: acompanhante + carro (família no plano Grátis)
A2: Valores puxados da aba Premissas.
A4: Família paga: acompanhante | B4: =Premissas!$B$5 -> 180
A5: Família paga: transporte | B5: =Premissas!$B$6 -> 80
A6: Família paga: taxa de serviço | B6: =Premissas!$B$8 -> 15
A7: Total pago pela família | B7: =SUM(B4:B6) -> 275
A9: Repasse ao acompanhante | B9: =-B4*Premissas!$B$18 -> -135
A10: Carro ida e volta | B10: =-Premissas!$B$19 -> -60
A11: Taxa de pagamento | B11: =-B7*Premissas!$B$21 -> -8.25
A12: Seguro | B12: =-Premissas!$B$22 -> -4
A13: IA + WhatsApp | B13: =-Premissas!$B$23 -> -3
A14: Impostos sobre a receita própria | B14: =-(B7+B9+B10)*Premissas!$B$25 -> -6.4
A15: Sobra para o Zelo (margem de contribuição) | B15: =B7+SUM(B9:B14) -> 58.35
A16: % do que a família pagou | B16: =IF(B7=0,0,B15/B7) -> 0.21218182
